2023-07-19 03:43:06,935 DEBUG    root            Loaded Command Group: ['gcloud', 'projects']
2023-07-19 03:43:06,936 DEBUG    root            Loaded Command Group: ['gcloud', 'projects', 'describe']
2023-07-19 03:43:06,937 DEBUG    root            Running [gcloud.projects.describe] with arguments: [--account: "ron.mcclain@figure-eight.com", --configuration: "default", --format: "value(name)", PROJECT_ID_OR_NUMBER: "devspace-256022"]
2023-07-19 03:43:06,952 DEBUG    urllib3.connectionpool Starting new HTTPS connection (1): cloudresourcemanager.googleapis.com:443
2023-07-19 03:43:06,954 DEBUG    root            Caught socket error, retrying: HTTPSConnectionPool(host='cloudresourcemanager.googleapis.com', port=443): Max retries exceeded with url: /v1/projects/devspace-256022?alt=json (Caused by NewConnectionError('<urllib3.connection.HTTPSConnection object at 0x105a70950>: Failed to establish a new connection: [Errno 8] nodename nor servname provided, or not known'))
2023-07-19 03:43:06,954 DEBUG    root            Retrying request to url https://cloudresourcemanager.googleapis.com/v1/projects/devspace-256022?alt=json after exception HTTPSConnectionPool(host='cloudresourcemanager.googleapis.com', port=443): Max retries exceeded with url: /v1/projects/devspace-256022?alt=json (Caused by NewConnectionError('<urllib3.connection.HTTPSConnection object at 0x105a70950>: Failed to establish a new connection: [Errno 8] nodename nor servname provided, or not known'))
2023-07-19 03:43:08,515 DEBUG    urllib3.connectionpool Starting new HTTPS connection (1): cloudresourcemanager.googleapis.com:443
2023-07-19 03:43:08,518 DEBUG    root            Caught socket error, retrying: HTTPSConnectionPool(host='cloudresourcemanager.googleapis.com', port=443): Max retries exceeded with url: /v1/projects/devspace-256022?alt=json (Caused by NewConnectionError('<urllib3.connection.HTTPSConnection object at 0x105b4c690>: Failed to establish a new connection: [Errno 8] nodename nor servname provided, or not known'))
2023-07-19 03:43:08,518 DEBUG    root            Retrying request to url https://cloudresourcemanager.googleapis.com/v1/projects/devspace-256022?alt=json after exception HTTPSConnectionPool(host='cloudresourcemanager.googleapis.com', port=443): Max retries exceeded with url: /v1/projects/devspace-256022?alt=json (Caused by NewConnectionError('<urllib3.connection.HTTPSConnection object at 0x105b4c690>: Failed to establish a new connection: [Errno 8] nodename nor servname provided, or not known'))
2023-07-19 03:43:11,931 DEBUG    urllib3.connectionpool Starting new HTTPS connection (1): cloudresourcemanager.googleapis.com:443
2023-07-19 03:43:11,936 DEBUG    root            Caught socket error, retrying: HTTPSConnectionPool(host='cloudresourcemanager.googleapis.com', port=443): Max retries exceeded with url: /v1/projects/devspace-256022?alt=json (Caused by NewConnectionError('<urllib3.connection.HTTPSConnection object at 0x105bd4b10>: Failed to establish a new connection: [Errno 8] nodename nor servname provided, or not known'))
2023-07-19 03:43:11,936 DEBUG    root            Retrying request to url https://cloudresourcemanager.googleapis.com/v1/projects/devspace-256022?alt=json after exception HTTPSConnectionPool(host='cloudresourcemanager.googleapis.com', port=443): Max retries exceeded with url: /v1/projects/devspace-256022?alt=json (Caused by NewConnectionError('<urllib3.connection.HTTPSConnection object at 0x105bd4b10>: Failed to establish a new connection: [Errno 8] nodename nor servname provided, or not known'))
2023-07-19 03:43:19,931 DEBUG    urllib3.connectionpool Starting new HTTPS connection (1): cloudresourcemanager.googleapis.com:443
2023-07-19 03:43:19,935 DEBUG    root            Caught socket error, retrying: HTTPSConnectionPool(host='cloudresourcemanager.googleapis.com', port=443): Max retries exceeded with url: /v1/projects/devspace-256022?alt=json (Caused by NewConnectionError('<urllib3.connection.HTTPSConnection object at 0x105bd4c90>: Failed to establish a new connection: [Errno 8] nodename nor servname provided, or not known'))
2023-07-19 03:43:19,935 DEBUG    root            Retrying request to url https://cloudresourcemanager.googleapis.com/v1/projects/devspace-256022?alt=json after exception HTTPSConnectionPool(host='cloudresourcemanager.googleapis.com', port=443): Max retries exceeded with url: /v1/projects/devspace-256022?alt=json (Caused by NewConnectionError('<urllib3.connection.HTTPSConnection object at 0x105bd4c90>: Failed to establish a new connection: [Errno 8] nodename nor servname provided, or not known'))
2023-07-19 03:43:36,200 DEBUG    urllib3.connectionpool Starting new HTTPS connection (1): cloudresourcemanager.googleapis.com:443
2023-07-19 03:43:36,204 DEBUG    root            HTTPSConnectionPool(host='cloudresourcemanager.googleapis.com', port=443): Max retries exceeded with url: /v1/projects/devspace-256022?alt=json (Caused by NewConnectionError('<urllib3.connection.HTTPSConnection object at 0x105bd4bd0>: Failed to establish a new connection: [Errno 8] nodename nor servname provided, or not known'))
Traceback (most recent call last):
  File "/opt/homebrew/Caskroom/google-cloud-sdk/428.0.0/google-cloud-sdk/lib/third_party/urllib3/connection.py", line 174, in _new_conn
    conn = connection.create_connection(
           ^^^^^^^^^^^^^^^^^^^^^^^^^^^^^
  File "/opt/homebrew/Caskroom/google-cloud-sdk/428.0.0/google-cloud-sdk/lib/third_party/urllib3/util/connection.py", line 72, in create_connection
    for res in socket.getaddrinfo(host, port, family, socket.SOCK_STREAM):
               ^^^^^^^^^^^^^^^^^^^^^^^^^^^^^^^^^^^^^^^^^^^^^^^^^^^^^^^^^^
  File "/opt/homebrew/Cellar/python@3.11/3.11.4_1/Frameworks/Python.framework/Versions/3.11/lib/python3.11/socket.py", line 962, in getaddrinfo
    for res in _socket.getaddrinfo(host, port, family, type, proto, flags):
               ^^^^^^^^^^^^^^^^^^^^^^^^^^^^^^^^^^^^^^^^^^^^^^^^^^^^^^^^^^^
socket.gaierror: [Errno 8] nodename nor servname provided, or not known

During handling of the above exception, another exception occurred:

Traceback (most recent call last):
  File "/opt/homebrew/Caskroom/google-cloud-sdk/428.0.0/google-cloud-sdk/lib/third_party/urllib3/connectionpool.py", line 717, in urlopen
    httplib_response = self._make_request(
                       ^^^^^^^^^^^^^^^^^^^
  File "/opt/homebrew/Caskroom/google-cloud-sdk/428.0.0/google-cloud-sdk/lib/third_party/urllib3/connectionpool.py", line 406, in _make_request
    self._validate_conn(conn)
  File "/opt/homebrew/Caskroom/google-cloud-sdk/428.0.0/google-cloud-sdk/lib/third_party/urllib3/connectionpool.py", line 1057, in _validate_conn
    conn.connect()
  File "/opt/homebrew/Caskroom/google-cloud-sdk/428.0.0/google-cloud-sdk/lib/third_party/urllib3/connection.py", line 358, in connect
    self.sock = conn = self._new_conn()
                       ^^^^^^^^^^^^^^^^
  File "/opt/homebrew/Caskroom/google-cloud-sdk/428.0.0/google-cloud-sdk/lib/third_party/urllib3/connection.py", line 186, in _new_conn
    raise NewConnectionError(
urllib3.exceptions.NewConnectionError: <urllib3.connection.HTTPSConnection object at 0x105bd4bd0>: Failed to establish a new connection: [Errno 8] nodename nor servname provided, or not known

During handling of the above exception, another exception occurred:

Traceback (most recent call last):
  File "/opt/homebrew/Caskroom/google-cloud-sdk/428.0.0/google-cloud-sdk/lib/third_party/requests/adapters.py", line 439, in send
    resp = conn.urlopen(
           ^^^^^^^^^^^^^
  File "/opt/homebrew/Caskroom/google-cloud-sdk/428.0.0/google-cloud-sdk/lib/third_party/urllib3/connectionpool.py", line 799, in urlopen
    retries = retries.increment(
              ^^^^^^^^^^^^^^^^^^
  File "/opt/homebrew/Caskroom/google-cloud-sdk/428.0.0/google-cloud-sdk/lib/third_party/urllib3/util/retry.py", line 592, in increment
    raise MaxRetryError(_pool, url, error or ResponseError(cause))
urllib3.exceptions.MaxRetryError: HTTPSConnectionPool(host='cloudresourcemanager.googleapis.com', port=443): Max retries exceeded with url: /v1/projects/devspace-256022?alt=json (Caused by NewConnectionError('<urllib3.connection.HTTPSConnection object at 0x105bd4bd0>: Failed to establish a new connection: [Errno 8] nodename nor servname provided, or not known'))

During handling of the above exception, another exception occurred:

Traceback (most recent call last):
  File "/opt/homebrew/share/google-cloud-sdk/lib/googlecloudsdk/calliope/cli.py", line 987, in Execute
    resources = calliope_command.Run(cli=self, args=args)
                ^^^^^^^^^^^^^^^^^^^^^^^^^^^^^^^^^^^^^^^^^
  File "/opt/homebrew/share/google-cloud-sdk/lib/googlecloudsdk/calliope/backend.py", line 807, in Run
    resources = command_instance.Run(args)
                ^^^^^^^^^^^^^^^^^^^^^^^^^^
  File "/opt/homebrew/share/google-cloud-sdk/lib/surface/projects/describe.py", line 51, in Run
    return projects_api.Get(project_ref)
           ^^^^^^^^^^^^^^^^^^^^^^^^^^^^^
  File "/opt/homebrew/share/google-cloud-sdk/lib/googlecloudsdk/api_lib/cloudresourcemanager/projects_api.py", line 129, in Get
    return client.projects.Get(
           ^^^^^^^^^^^^^^^^^^^^
  File "/opt/homebrew/share/google-cloud-sdk/lib/googlecloudsdk/generated_clients/apis/cloudresourcemanager/v1/cloudresourcemanager_v1_client.py", line 758, in Get
    return self._RunMethod(
           ^^^^^^^^^^^^^^^^
  File "/opt/homebrew/Caskroom/google-cloud-sdk/428.0.0/google-cloud-sdk/lib/third_party/apitools/base/py/base_api.py", line 734, in _RunMethod
    http_response = http_wrapper.MakeRequest(
                    ^^^^^^^^^^^^^^^^^^^^^^^^^
  File "/opt/homebrew/Caskroom/google-cloud-sdk/428.0.0/google-cloud-sdk/lib/third_party/apitools/base/py/http_wrapper.py", line 348, in MakeRequest
    return _MakeRequestNoRetry(
           ^^^^^^^^^^^^^^^^^^^^
  File "/opt/homebrew/Caskroom/google-cloud-sdk/428.0.0/google-cloud-sdk/lib/third_party/apitools/base/py/http_wrapper.py", line 397, in _MakeRequestNoRetry
    info, content = http.request(
                    ^^^^^^^^^^^^^
  File "/opt/homebrew/share/google-cloud-sdk/lib/googlecloudsdk/core/requests.py", line 426, in HttpRequest
    return orig_request_method(*args, **kwargs)
           ^^^^^^^^^^^^^^^^^^^^^^^^^^^^^^^^^^^^
  File "/opt/homebrew/share/google-cloud-sdk/lib/googlecloudsdk/core/requests.py", line 510, in request
    response = self.session.request(
               ^^^^^^^^^^^^^^^^^^^^^
  File "/opt/homebrew/share/google-cloud-sdk/lib/googlecloudsdk/core/transport.py", line 260, in WrappedRequest
    response = orig_request(*modified_args, **modified_kwargs)
               ^^^^^^^^^^^^^^^^^^^^^^^^^^^^^^^^^^^^^^^^^^^^^^^
  File "/opt/homebrew/share/google-cloud-sdk/lib/googlecloudsdk/core/credentials/requests.py", line 107, in WrappedRequest
    response = orig_request(
               ^^^^^^^^^^^^^
  File "/opt/homebrew/share/google-cloud-sdk/lib/googlecloudsdk/core/transport.py", line 260, in WrappedRequest
    response = orig_request(*modified_args, **modified_kwargs)
               ^^^^^^^^^^^^^^^^^^^^^^^^^^^^^^^^^^^^^^^^^^^^^^^
  File "/opt/homebrew/share/google-cloud-sdk/lib/googlecloudsdk/core/requests.py", line 246, in WrappedRequest
    return orig_request_method(*args, **kwargs)
           ^^^^^^^^^^^^^^^^^^^^^^^^^^^^^^^^^^^^
  File "/opt/homebrew/Caskroom/google-cloud-sdk/428.0.0/google-cloud-sdk/lib/third_party/requests/sessions.py", line 542, in request
    resp = self.send(prep, **send_kwargs)
           ^^^^^^^^^^^^^^^^^^^^^^^^^^^^^^
  File "/opt/homebrew/Caskroom/google-cloud-sdk/428.0.0/google-cloud-sdk/lib/third_party/requests/sessions.py", line 655, in send
    r = adapter.send(request, **kwargs)
        ^^^^^^^^^^^^^^^^^^^^^^^^^^^^^^^
  File "/opt/homebrew/Caskroom/google-cloud-sdk/428.0.0/google-cloud-sdk/lib/third_party/requests/adapters.py", line 516, in send
    raise ConnectionError(e, request=request)
requests.exceptions.ConnectionError: HTTPSConnectionPool(host='cloudresourcemanager.googleapis.com', port=443): Max retries exceeded with url: /v1/projects/devspace-256022?alt=json (Caused by NewConnectionError('<urllib3.connection.HTTPSConnection object at 0x105bd4bd0>: Failed to establish a new connection: [Errno 8] nodename nor servname provided, or not known'))
2023-07-19 03:43:36,230 ERROR    ___FILE_ONLY___ BEGIN CRASH STACKTRACE
Traceback (most recent call last):
  File "/opt/homebrew/Caskroom/google-cloud-sdk/428.0.0/google-cloud-sdk/lib/third_party/urllib3/connection.py", line 174, in _new_conn
    conn = connection.create_connection(
           ^^^^^^^^^^^^^^^^^^^^^^^^^^^^^
  File "/opt/homebrew/Caskroom/google-cloud-sdk/428.0.0/google-cloud-sdk/lib/third_party/urllib3/util/connection.py", line 72, in create_connection
    for res in socket.getaddrinfo(host, port, family, socket.SOCK_STREAM):
               ^^^^^^^^^^^^^^^^^^^^^^^^^^^^^^^^^^^^^^^^^^^^^^^^^^^^^^^^^^
  File "/opt/homebrew/Cellar/python@3.11/3.11.4_1/Frameworks/Python.framework/Versions/3.11/lib/python3.11/socket.py", line 962, in getaddrinfo
    for res in _socket.getaddrinfo(host, port, family, type, proto, flags):
               ^^^^^^^^^^^^^^^^^^^^^^^^^^^^^^^^^^^^^^^^^^^^^^^^^^^^^^^^^^^
socket.gaierror: [Errno 8] nodename nor servname provided, or not known

During handling of the above exception, another exception occurred:

Traceback (most recent call last):
  File "/opt/homebrew/Caskroom/google-cloud-sdk/428.0.0/google-cloud-sdk/lib/third_party/urllib3/connectionpool.py", line 717, in urlopen
    httplib_response = self._make_request(
                       ^^^^^^^^^^^^^^^^^^^
  File "/opt/homebrew/Caskroom/google-cloud-sdk/428.0.0/google-cloud-sdk/lib/third_party/urllib3/connectionpool.py", line 406, in _make_request
    self._validate_conn(conn)
  File "/opt/homebrew/Caskroom/google-cloud-sdk/428.0.0/google-cloud-sdk/lib/third_party/urllib3/connectionpool.py", line 1057, in _validate_conn
    conn.connect()
  File "/opt/homebrew/Caskroom/google-cloud-sdk/428.0.0/google-cloud-sdk/lib/third_party/urllib3/connection.py", line 358, in connect
    self.sock = conn = self._new_conn()
                       ^^^^^^^^^^^^^^^^
  File "/opt/homebrew/Caskroom/google-cloud-sdk/428.0.0/google-cloud-sdk/lib/third_party/urllib3/connection.py", line 186, in _new_conn
    raise NewConnectionError(
urllib3.exceptions.NewConnectionError: <urllib3.connection.HTTPSConnection object at 0x105bd4bd0>: Failed to establish a new connection: [Errno 8] nodename nor servname provided, or not known

During handling of the above exception, another exception occurred:

Traceback (most recent call last):
  File "/opt/homebrew/Caskroom/google-cloud-sdk/428.0.0/google-cloud-sdk/lib/third_party/requests/adapters.py", line 439, in send
    resp = conn.urlopen(
           ^^^^^^^^^^^^^
  File "/opt/homebrew/Caskroom/google-cloud-sdk/428.0.0/google-cloud-sdk/lib/third_party/urllib3/connectionpool.py", line 799, in urlopen
    retries = retries.increment(
              ^^^^^^^^^^^^^^^^^^
  File "/opt/homebrew/Caskroom/google-cloud-sdk/428.0.0/google-cloud-sdk/lib/third_party/urllib3/util/retry.py", line 592, in increment
    raise MaxRetryError(_pool, url, error or ResponseError(cause))
urllib3.exceptions.MaxRetryError: HTTPSConnectionPool(host='cloudresourcemanager.googleapis.com', port=443): Max retries exceeded with url: /v1/projects/devspace-256022?alt=json (Caused by NewConnectionError('<urllib3.connection.HTTPSConnection object at 0x105bd4bd0>: Failed to establish a new connection: [Errno 8] nodename nor servname provided, or not known'))

During handling of the above exception, another exception occurred:

Traceback (most recent call last):
  File "/opt/homebrew/share/google-cloud-sdk/lib/googlecloudsdk/command_lib/crash_handling.py", line 191, in Wrapper
    target_function(*args, **kwargs)
  File "/opt/homebrew/share/google-cloud-sdk/lib/googlecloudsdk/gcloud_main.py", line 186, in main
    gcloud_cli.Execute()
  File "/opt/homebrew/share/google-cloud-sdk/lib/googlecloudsdk/calliope/cli.py", line 1013, in Execute
    self._HandleAllErrors(exc, command_path_string, specified_arg_names)
  File "/opt/homebrew/share/google-cloud-sdk/lib/googlecloudsdk/calliope/cli.py", line 1050, in _HandleAllErrors
    exceptions.HandleError(exc, command_path_string, self.__known_error_handler)
  File "/opt/homebrew/share/google-cloud-sdk/lib/googlecloudsdk/calliope/exceptions.py", line 555, in HandleError
    core_exceptions.reraise(exc)
  File "/opt/homebrew/share/google-cloud-sdk/lib/googlecloudsdk/core/exceptions.py", line 146, in reraise
    six.reraise(type(exc_value), exc_value, tb)
  File "/opt/homebrew/Caskroom/google-cloud-sdk/428.0.0/google-cloud-sdk/lib/third_party/six/__init__.py", line 719, in reraise
    raise value
  File "/opt/homebrew/share/google-cloud-sdk/lib/googlecloudsdk/calliope/cli.py", line 987, in Execute
    resources = calliope_command.Run(cli=self, args=args)
                ^^^^^^^^^^^^^^^^^^^^^^^^^^^^^^^^^^^^^^^^^
  File "/opt/homebrew/share/google-cloud-sdk/lib/googlecloudsdk/calliope/backend.py", line 807, in Run
    resources = command_instance.Run(args)
                ^^^^^^^^^^^^^^^^^^^^^^^^^^
  File "/opt/homebrew/share/google-cloud-sdk/lib/surface/projects/describe.py", line 51, in Run
    return projects_api.Get(project_ref)
           ^^^^^^^^^^^^^^^^^^^^^^^^^^^^^
  File "/opt/homebrew/share/google-cloud-sdk/lib/googlecloudsdk/api_lib/cloudresourcemanager/projects_api.py", line 129, in Get
    return client.projects.Get(
           ^^^^^^^^^^^^^^^^^^^^
  File "/opt/homebrew/share/google-cloud-sdk/lib/googlecloudsdk/generated_clients/apis/cloudresourcemanager/v1/cloudresourcemanager_v1_client.py", line 758, in Get
    return self._RunMethod(
           ^^^^^^^^^^^^^^^^
  File "/opt/homebrew/Caskroom/google-cloud-sdk/428.0.0/google-cloud-sdk/lib/third_party/apitools/base/py/base_api.py", line 734, in _RunMethod
    http_response = http_wrapper.MakeRequest(
                    ^^^^^^^^^^^^^^^^^^^^^^^^^
  File "/opt/homebrew/Caskroom/google-cloud-sdk/428.0.0/google-cloud-sdk/lib/third_party/apitools/base/py/http_wrapper.py", line 348, in MakeRequest
    return _MakeRequestNoRetry(
           ^^^^^^^^^^^^^^^^^^^^
  File "/opt/homebrew/Caskroom/google-cloud-sdk/428.0.0/google-cloud-sdk/lib/third_party/apitools/base/py/http_wrapper.py", line 397, in _MakeRequestNoRetry
    info, content = http.request(
                    ^^^^^^^^^^^^^
  File "/opt/homebrew/share/google-cloud-sdk/lib/googlecloudsdk/core/requests.py", line 426, in HttpRequest
    return orig_request_method(*args, **kwargs)
           ^^^^^^^^^^^^^^^^^^^^^^^^^^^^^^^^^^^^
  File "/opt/homebrew/share/google-cloud-sdk/lib/googlecloudsdk/core/requests.py", line 510, in request
    response = self.session.request(
               ^^^^^^^^^^^^^^^^^^^^^
  File "/opt/homebrew/share/google-cloud-sdk/lib/googlecloudsdk/core/transport.py", line 260, in WrappedRequest
    response = orig_request(*modified_args, **modified_kwargs)
               ^^^^^^^^^^^^^^^^^^^^^^^^^^^^^^^^^^^^^^^^^^^^^^^
  File "/opt/homebrew/share/google-cloud-sdk/lib/googlecloudsdk/core/credentials/requests.py", line 107, in WrappedRequest
    response = orig_request(
               ^^^^^^^^^^^^^
  File "/opt/homebrew/share/google-cloud-sdk/lib/googlecloudsdk/core/transport.py", line 260, in WrappedRequest
    response = orig_request(*modified_args, **modified_kwargs)
               ^^^^^^^^^^^^^^^^^^^^^^^^^^^^^^^^^^^^^^^^^^^^^^^
  File "/opt/homebrew/share/google-cloud-sdk/lib/googlecloudsdk/core/requests.py", line 246, in WrappedRequest
    return orig_request_method(*args, **kwargs)
           ^^^^^^^^^^^^^^^^^^^^^^^^^^^^^^^^^^^^
  File "/opt/homebrew/Caskroom/google-cloud-sdk/428.0.0/google-cloud-sdk/lib/third_party/requests/sessions.py", line 542, in request
    resp = self.send(prep, **send_kwargs)
           ^^^^^^^^^^^^^^^^^^^^^^^^^^^^^^
  File "/opt/homebrew/Caskroom/google-cloud-sdk/428.0.0/google-cloud-sdk/lib/third_party/requests/sessions.py", line 655, in send
    r = adapter.send(request, **kwargs)
        ^^^^^^^^^^^^^^^^^^^^^^^^^^^^^^^
  File "/opt/homebrew/Caskroom/google-cloud-sdk/428.0.0/google-cloud-sdk/lib/third_party/requests/adapters.py", line 516, in send
    raise ConnectionError(e, request=request)
requests.exceptions.ConnectionError: HTTPSConnectionPool(host='cloudresourcemanager.googleapis.com', port=443): Max retries exceeded with url: /v1/projects/devspace-256022?alt=json (Caused by NewConnectionError('<urllib3.connection.HTTPSConnection object at 0x105bd4bd0>: Failed to establish a new connection: [Errno 8] nodename nor servname provided, or not known'))
2023-07-19 03:43:36,237 ERROR    root            gcloud crashed (ConnectionError): HTTPSConnectionPool(host='cloudresourcemanager.googleapis.com', port=443): Max retries exceeded with url: /v1/projects/devspace-256022?alt=json (Caused by NewConnectionError('<urllib3.connection.HTTPSConnection object at 0x105bd4bd0>: Failed to establish a new connection: [Errno 8] nodename nor servname provided, or not known'))
2023-07-19 03:43:36,238 INFO     ___FILE_ONLY___ 
If you would like to report this issue, please run the following command:

2023-07-19 03:43:36,238 INFO     ___FILE_ONLY___   gcloud feedback

2023-07-19 03:43:36,238 INFO     ___FILE_ONLY___ 
To check gcloud for common problems, please run the following command:

2023-07-19 03:43:36,238 INFO     ___FILE_ONLY___   gcloud info --run-diagnostics

